{
  "Header": {
    "Original": "CVE-2024-56374 (An issue was discovered in Django 5.1 before 5.1.5, 5.0 before 5.0.11, ...)",
    "ID": "CVE-2024-56374",
    "Description": "(An issue was discovered in Django 5.1 before 5.1.5, 5.0 before 5.0.11, ...)"
  },
  "Annotations": [
    {
      "Original": "{DLA-4030-1}",
      "Type": "xref",
      "Bugs": [
        "DLA-4030-1"
      ]
    },
    {
      "Original": "- python-django 3:4.2.18-1 (bug #1093049)",
      "Type": "package",
      "Package": "python-django",
      "Kind": "fixed",
      "Version": "3:4.2.18-1",
      "BugNo": 1093049
    },
    {
      "Original": "NOTE: https://www.djangoproject.com/weblog/2025/jan/14/security-releases/",
      "Type": "NOTE",
      "Description": "https://www.djangoproject.com/weblog/2025/jan/14/security-releases/"
    },
    {
      "Original": "NOTE: Fixed by: https://github.com/django/django/commit/ad866a1ca3e7d60da888d25d27e46a8adb2ed36e (4.2.18)",
      "Type": "NOTE",
      "Description": "Fixed by: https://github.com/django/django/commit/ad866a1ca3e7d60da888d25d27e46a8adb2ed36e (4.2.18)"
    }
  ]
}