{
  "Header": {
    "Original": "CVE-2024-39329 (An issue was discovered in Django 5.0 before 5.0.7 and 4.2 before 4.2. ...)",
    "ID": "CVE-2024-39329",
    "Description": "(An issue was discovered in Django 5.0 before 5.0.7 and 4.2 before 4.2. ...)"
  },
  "Annotations": [
    {
      "Original": "- python-django 3:4.2.14-1 (bug #1076069)",
      "Type": "package",
      "Package": "python-django",
      "Kind": "fixed",
      "Version": "3:4.2.14-1",
      "BugNo": 1076069
    },
    {
      "Original": "NOTE: https://www.djangoproject.com/weblog/2024/jul/09/security-releases/",
      "Type": "NOTE",
      "Description": "https://www.djangoproject.com/weblog/2024/jul/09/security-releases/"
    },
    {
      "Original": "NOTE: https://github.com/django/django/commit/156d3186c96e3ec2ca73b8b25dc2ef366e38df14 (4.2.14)",
      "Type": "NOTE",
      "Description": "https://github.com/django/django/commit/156d3186c96e3ec2ca73b8b25dc2ef366e38df14 (4.2.14)"
    }
  ]
}