{
  "Header": {
    "Original": "CVE-2024-53908 (An issue was discovered in Django 5.1 before 5.1.4, 5.0 before 5.0.10, ...)",
    "ID": "CVE-2024-53908",
    "Description": "(An issue was discovered in Django 5.1 before 5.1.4, 5.0 before 5.0.10, ...)"
  },
  "Annotations": [
    {
      "Original": "- python-django 3:4.2.17-1",
      "Type": "package",
      "Package": "python-django",
      "Kind": "fixed",
      "Version": "3:4.2.17-1"
    },
    {
      "Original": "NOTE: https://www.djangoproject.com/weblog/2024/dec/04/security-releases/",
      "Type": "NOTE",
      "Description": "https://www.djangoproject.com/weblog/2024/dec/04/security-releases/"
    },
    {
      "Original": "NOTE: Fixed by: https://github.com/django/django/commit/7376bcbf508883282ffcc0f0fac5cf0ed2d6cbc5 (4.2.17)",
      "Type": "NOTE",
      "Description": "Fixed by: https://github.com/django/django/commit/7376bcbf508883282ffcc0f0fac5cf0ed2d6cbc5 (4.2.17)"
    }
  ]
}