{
  "Header": {
    "Original": "CVE-2024-9979 (A flaw was found in PyO3. This vulnerability causes a use-after-free i ...)",
    "ID": "CVE-2024-9979",
    "Description": "(A flaw was found in PyO3. This vulnerability causes a use-after-free i ...)"
  },
  "Annotations": [
    {
      "Original": "- rust-pyo3 0.22.5-1 (bug #1085296)",
      "Type": "package",
      "Package": "rust-pyo3",
      "Kind": "fixed",
      "Version": "0.22.5-1",
      "BugNo": 1085296
    },
    {
      "Original": "[bookworm] - rust-pyo3 \u003cnot-affected\u003e (Vulnerable code introduced later)",
      "Type": "package",
      "Release": "bookworm",
      "Package": "rust-pyo3",
      "Kind": "not-affected",
      "Description": "Vulnerable code introduced later"
    },
    {
      "Original": "NOTE: https://github.com/PyO3/pyo3/pull/4590",
      "Type": "NOTE",
      "Description": "https://github.com/PyO3/pyo3/pull/4590"
    },
    {
      "Original": "NOTE: https://rustsec.org/advisories/RUSTSEC-2024-0378.html",
      "Type": "NOTE",
      "Description": "https://rustsec.org/advisories/RUSTSEC-2024-0378.html"
    }
  ]
}