{
  "Header": {
    "Original": "CVE-2024-4109 (A flaw was found in Undertow. An HTTP request header value from a prev ...)",
    "ID": "CVE-2024-4109",
    "Description": "(A flaw was found in Undertow. An HTTP request header value from a prev ...)"
  },
  "Annotations": [
    {
      "Original": "- undertow \u003cunfixed\u003e",
      "Type": "package",
      "Package": "undertow",
      "Kind": "unfixed"
    },
    {
      "Original": "NOTE: https://bugzilla.redhat.com/show_bug.cgi?id=2272325",
      "Type": "NOTE",
      "Description": "https://bugzilla.redhat.com/show_bug.cgi?id=2272325"
    },
    {
      "Original": "NOTE: https://github.com/undertow-io/undertow/pull/1668",
      "Type": "NOTE",
      "Description": "https://github.com/undertow-io/undertow/pull/1668"
    },
    {
      "Original": "NOTE: https://issues.redhat.com/browse/UNDERTOW-2451",
      "Type": "NOTE",
      "Description": "https://issues.redhat.com/browse/UNDERTOW-2451"
    },
    {
      "Original": "NOTE: Fixed by: https://github.com/undertow-io/undertow/pull/1715",
      "Type": "NOTE",
      "Description": "Fixed by: https://github.com/undertow-io/undertow/pull/1715"
    }
  ]
}