{
  "Header": {
    "Original": "CVE-2024-42005 (An issue was discovered in Django 5.0 before 5.0.8 and 4.2 before 4.2. ...)",
    "ID": "CVE-2024-42005",
    "Description": "(An issue was discovered in Django 5.0 before 5.0.8 and 4.2 before 4.2. ...)"
  },
  "Annotations": [
    {
      "Original": "- python-django 3:4.2.15-1 (bug #1078074)",
      "Type": "package",
      "Package": "python-django",
      "Kind": "fixed",
      "Version": "3:4.2.15-1",
      "BugNo": 1078074
    },
    {
      "Original": "NOTE: https://www.djangoproject.com/weblog/2024/aug/06/security-releases/",
      "Type": "NOTE",
      "Description": "https://www.djangoproject.com/weblog/2024/aug/06/security-releases/"
    },
    {
      "Original": "NOTE: https://github.com/django/django/commit/f4af67b9b41e0f4c117a8741da3abbd1c869ab28/ (4.2.15)",
      "Type": "NOTE",
      "Description": "https://github.com/django/django/commit/f4af67b9b41e0f4c117a8741da3abbd1c869ab28/ (4.2.15)"
    }
  ]
}