{
  "Header": {
    "Original": "CVE-2025-26699 (An issue was discovered in Django 5.1 before 5.1.7, 5.0 before 5.0.13, ...)",
    "ID": "CVE-2025-26699",
    "Description": "(An issue was discovered in Django 5.1 before 5.1.7, 5.0 before 5.0.13, ...)"
  },
  "Annotations": [
    {
      "Original": "{DLA-4086-1}",
      "Type": "xref",
      "Bugs": [
        "DLA-4086-1"
      ]
    },
    {
      "Original": "- python-django 3:4.2.20-1 (bug #1099682)",
      "Type": "package",
      "Package": "python-django",
      "Kind": "fixed",
      "Version": "3:4.2.20-1",
      "BugNo": 1099682
    },
    {
      "Original": "NOTE: https://www.djangoproject.com/weblog/2025/mar/06/security-releases/",
      "Type": "NOTE",
      "Description": "https://www.djangoproject.com/weblog/2025/mar/06/security-releases/"
    },
    {
      "Original": "NOTE: Fixed by: https://github.com/django/django/commit/e88f7376fe68dbf4ebaf11fad1513ce700b45860 (4.2.20)",
      "Type": "NOTE",
      "Description": "Fixed by: https://github.com/django/django/commit/e88f7376fe68dbf4ebaf11fad1513ce700b45860 (4.2.20)"
    }
  ]
}