{
  "Header": {
    "Original": "CVE-2025-32913 (A flaw was found in libsoup, where the soup_message_headers_get_conten ...)",
    "ID": "CVE-2025-32913",
    "Description": "(A flaw was found in libsoup, where the soup_message_headers_get_conten ...)"
  },
  "Annotations": [
    {
      "Original": "{DLA-4140-1}",
      "Type": "xref",
      "Bugs": [
        "DLA-4140-1"
      ]
    },
    {
      "Original": "- libsoup3 3.6.4-1",
      "Type": "package",
      "Package": "libsoup3",
      "Kind": "fixed",
      "Version": "3.6.4-1"
    },
    {
      "Original": "- libsoup2.4 \u003cunfixed\u003e (bug #1103515)",
      "Type": "package",
      "Package": "libsoup2.4",
      "Kind": "unfixed",
      "BugNo": 1103515
    },
    {
      "Original": "NOTE: https://gitlab.gnome.org/GNOME/libsoup/-/issues/435",
      "Type": "NOTE",
      "Description": "https://gitlab.gnome.org/GNOME/libsoup/-/issues/435"
    },
    {
      "Original": "NOTE: https://gitlab.gnome.org/GNOME/libsoup/-/merge_requests/422",
      "Type": "NOTE",
      "Description": "https://gitlab.gnome.org/GNOME/libsoup/-/merge_requests/422"
    },
    {
      "Original": "NOTE: Fixed by: https://gitlab.gnome.org/GNOME/libsoup/-/commit/f4a761fb66512fff59798765e8ac5b9e57dceef0 (3.6.2)",
      "Type": "NOTE",
      "Description": "Fixed by: https://gitlab.gnome.org/GNOME/libsoup/-/commit/f4a761fb66512fff59798765e8ac5b9e57dceef0 (3.6.2)"
    }
  ]
}